#VRML_SIM R2020b utf8
WorldInfo {
  coordinateSystem "NUE"
}
Viewpoint {
  orientation 0.28031590892440933 -0.9219090578129351 -0.2674073303526827 4.701263773885951
  position 0.7154976093960287 1.6127231647715596 0.13756106365774806
}
TexturedBackground {
}
TexturedBackgroundLight {
}
Floor {
}
DEF Sentinel Robot {
  translation 0 1.155 0
  children [
    DEF On_Driven_Wheel_1 HingeJoint {
      jointParameters HingeJointParameters {
        axis 0 0 1
        anchor 0 0.117 -0.064
      }
      endPoint Solid {
        translation 0 0.117 -0.064
        rotation 1 0 0 1.5708
        children [
          DEF On_Driven_Wheel Shape {
            appearance PBRAppearance {
              baseColor 1 0.666667 0.498039
            }
            geometry Cylinder {
              height 0.01
              radius 0.009
            }
          }
        ]
        name "solid(6)"
        boundingObject USE On_Driven_Wheel
        physics Physics {
        }
      }
    }
    DEF On_Driven_Wheel_2 HingeJoint {
      jointParameters HingeJointParameters {
        axis 0 0 1
        anchor 0 0.117 0.064
      }
      device [
        RotationalMotor {
          name "motor1"
        }
      ]
      endPoint Solid {
        translation 0 0.117 0.064
        rotation 1 0 0 1.5708
        children [
          DEF On_Driven_Wheel Shape {
            appearance PBRAppearance {
              baseColor 1 0.666667 0.498039
            }
            geometry Cylinder {
              height 0.01
              radius 0.009
            }
          }
        ]
        name "solid(5)"
        boundingObject USE On_Driven_Wheel
        physics Physics {
        }
      }
    }
    DEF Doen_Driven_Wheel_1 HingeJoint {
      jointParameters HingeJointParameters {
        axis 0 0 1
        anchor 0 0.035 0.06
      }
      endPoint Solid {
        translation 0 0.035 0.06
        rotation 1 0 0 1.5708
        children [
          DEF Doen_Driven_Wheel Shape {
            appearance PBRAppearance {
              baseColor 1 0.666667 0.498039
            }
            geometry Cylinder {
              height 0.015
              radius 0.03
            }
          }
        ]
        name "solid(1)"
        boundingObject USE Doen_Driven_Wheel
        physics Physics {
        }
      }
    }
    DEF Doen_Driven_Wheel_2 HingeJoint {
      jointParameters HingeJointParameters {
        axis 0 0 1
        anchor 0 0.035 -0.06
      }
      endPoint Solid {
        translation 0 0.035 -0.06
        rotation 1 0 0 1.5708
        children [
          DEF Doen_Driven_Wheel Shape {
            appearance PBRAppearance {
              baseColor 1 0.666667 0.498039
            }
            geometry Cylinder {
              height 0.015
              radius 0.03
            }
          }
        ]
        name "solid(2)"
        boundingObject USE Doen_Driven_Wheel
        physics Physics {
        }
      }
    }
    DEF Intermediate_Driven_Wheel_1 HingeJoint {
      jointParameters HingeJointParameters {
        axis 0 1 0
        anchor 0 0.08 0.114
      }
      endPoint Solid {
        translation 0 0.08 0.114
        rotation 1 0 0 0
        children [
          DEF Intermediate_Driven_Wheel Shape {
            appearance PBRAppearance {
              baseColor 1 0.666667 0.498039
            }
            geometry Cylinder {
              height 0.01
              radius 0.015
            }
          }
        ]
        name "solid(3)"
        boundingObject USE Intermediate_Driven_Wheel
        physics Physics {
        }
      }
    }
    DEF Intermediate_Driven_Wheel_2 HingeJoint {
      jointParameters HingeJointParameters {
        axis 0 1 0
        anchor 0 0.08 -0.114
      }
      endPoint Solid {
        translation 0 0.08 -0.114
        rotation 1 0 0 0
        children [
          DEF Intermediate_Driven_Wheel Shape {
            appearance PBRAppearance {
              baseColor 1 0.666667 0.498039
            }
            geometry Cylinder {
              height 0.01
              radius 0.015
            }
          }
        ]
        name "solid(4)"
        boundingObject USE Intermediate_Driven_Wheel
        physics Physics {
        }
      }
    }
    DEF Frame Transform {
      children [
        DEF Frame Group {
          children [
            Transform {
              translation 0 0.13 0
              children [
                Shape {
                  appearance PBRAppearance {
                    baseColor 1 0 0.498039
                  }
                  geometry Box {
                    size 0.04 0.01 0.31
                  }
                }
              ]
            }
            Transform {
              translation 0 0.08 -0.14
              children [
                Shape {
                  appearance PBRAppearance {
                    baseColor 1 0 0.498039
                  }
                  geometry Box {
                    size 0.03 0.01 0.025
                  }
                }
              ]
            }
            Transform {
              translation 0 0.08 0.14
              children [
                Shape {
                  appearance PBRAppearance {
                    baseColor 1 0 0.498039
                  }
                  geometry Box {
                    size 0.03 0.01 0.025
                  }
                }
              ]
            }
            Transform {
              translation 0 0.065 -0.16
              children [
                Shape {
                  appearance PBRAppearance {
                    baseColor 1 0 0.498039
                  }
                  geometry Box {
                    size 0.3 0.15 0.02
                  }
                }
              ]
            }
            Transform {
              translation 0 0.065 0.16
              children [
                Shape {
                  appearance PBRAppearance {
                    baseColor 1 0 0.498039
                  }
                  geometry Box {
                    size 0.3 0.15 0.02
                  }
                }
              ]
            }
            Shape {
              appearance PBRAppearance {
                baseColor 1 0 0.498039
              }
              geometry Box {
                size 0.1 0.02 0.3
              }
            }
          ]
        }
      ]
    }
  ]
  boundingObject USE Frame
  physics Physics {
    density -1
    mass 10
  }
  controller "my_controller"
}
Solid {
  translation 0 1.24 0
  children [
    DEF track Group {
      children [
        Transform {
          translation 0 -1.2 0
          children [
            Shape {
              appearance PBRAppearance {
                baseColor 0 0 1
              }
              geometry Box {
                size 3.4 0.05 2.9
              }
            }
          ]
        }
        Transform {
          translation 1.19 -0.57 0
          children [
            Shape {
              appearance PBRAppearance {
                baseColor 0.666667 0 0
              }
              geometry Cylinder {
                height 1.2
                radius 0.1
              }
            }
          ]
        }
        Transform {
          translation -1.19 -0.57 0
          children [
            Shape {
              appearance PBRAppearance {
                baseColor 0.666667 0 0
              }
              geometry Cylinder {
                height 1.2
                radius 0.1
              }
            }
          ]
        }
        Shape {
          appearance PBRAppearance {
            baseColor 0 0.666667 0
          }
          geometry Box {
            size 2.6 0.05 0.2
          }
        }
      ]
    }
  ]
  boundingObject USE track
  physics Physics {
    density -1
    mass 20
  }
}
