#VRML_SIM R2021a utf8
WorldInfo {
  basicTimeStep 8
  coordinateSystem "NUE"
}
Viewpoint {
  orientation 0.9647745202848008 -0.25584729594964994 -0.0612559071803247 5.796682737922136
  position 0.47882879116635285 2.3654275753817013 2.1245000522084245
}
TexturedBackground {
}
TexturedBackgroundLight {
}
Floor {
}
Solid {
  translation 1.38 0 -3.33
  children [
    DEF BOX_1 Shape {
      appearance PBRAppearance {
        baseColor 0 1 1
        metalness 0
      }
      geometry Box {
        size 0.3 0.3 0.1
      }
    }
  ]
  name "solid(1)"
  boundingObject USE BOX_1
  physics Physics {
  }
  recognitionColors [
    0 1 1
  ]
}
DEF Sentinel Robot {
  translation 0 1.155 0
  children [
    DEF Cloud Transform {
      translation 0 -0.02 0
      children [
        HingeJoint {
          jointParameters HingeJointParameters {
            axis 0 1 0
          }
          device [
            RotationalMotor {
              name "motor2"
              maxVelocity 50
            }
          ]
          endPoint Solid {
            children [
              DEF shoot Group {
                children [
                  HingeJoint {
                    jointParameters HingeJointParameters {
                      anchor -0.09 -0.11 0
                    }
                    device [
                      RotationalMotor {
                        name "motor3"
                        maxVelocity 50
                      }
                    ]
                    endPoint Solid {
                      translation -0.0899999 -0.11 0
                      rotation 0 0 1 -1.5707953071795862
                      children [
                        Transform {
                          translation 0 0.09 0
                          rotation 0 0 1 -1.5707953071795862
                          children [
                            Solid {
                              rotation 1 0 0 3.14159
                              children [
                                DistanceSensor {
                                  translation -4.07848e-08 0.01 0.22
                                  rotation 0 1 0 -1.5707953071795862
                                  children [
                                    Transform {
                                      rotation -0.577349935856137 0.577349935856137 0.5773509358560258 2.09439
                                      children [
                                        Shape {
                                          appearance PBRAppearance {
                                            baseColor 1 1 0
                                            metalness 0
                                          }
                                          geometry Cylinder {
                                            height 0.01
                                            radius 0.01
                                          }
                                        }
                                      ]
                                    }
                                  ]
                                  name "laser0"
                                  lookupTable [
                                    0 0 0
                                    10 10 0
                                  ]
                                  type "laser"
                                  aperture 0.005
                                }
                                Camera {
                                  translation 0 0.01 0.21
                                  rotation 0 1 0 3.14159
                                  children [
                                    Transform {
                                      rotation 1 0 0 -1.5707953071795862
                                      children [
                                        Shape {
                                          appearance PBRAppearance {
                                            baseColor 1 1 0
                                            metalness 0
                                          }
                                          geometry Cylinder {
                                            height 0.04
                                            radius 0.01
                                          }
                                        }
                                      ]
                                    }
                                  ]
                                  name "camera1"
                                  width 1280
                                  height 800
                                  recognition Recognition {
                                    frameColor 0 1 0
                                    frameThickness 3
                                  }
                                }
                                Transform {
                                  translation 0 -0.01 0.07
                                  children [
                                    Solid {
                                      translation 0 0 0.06
                                      children [
                                        DEF barrel Shape {
                                          appearance PBRAppearance {
                                            baseColor 0.12549 0.12549 0.12549
                                          }
                                          geometry Box {
                                            size 0.03 0.015 0.2
                                          }
                                        }
                                      ]
                                      name "solid(8)"
                                      boundingObject USE barrel
                                      physics Physics {
                                      }
                                    }
                                  ]
                                }
                                DEF shoot_board Shape {
                                  appearance PBRAppearance {
                                    baseColor 0.12549 0.12549 0.12549
                                  }
                                  geometry Box {
                                    size 0.17 0.01 0.1
                                  }
                                }
                              ]
                              name "solid(7)"
                              boundingObject USE shoot_board
                              physics Physics {
                              }
                            }
                          ]
                        }
                        HingeJoint {
                          jointParameters HingeJointParameters {
                            axis 0 1 0
                            anchor 0 0.18 0
                          }
                          endPoint Solid {
                            translation 0 0.18 0
                            children [
                              DEF Cloud_false_Motor Shape {
                                appearance PBRAppearance {
                                  baseColor 0 0 0
                                }
                                geometry Cylinder {
                                  height 0.02
                                  radius 0.055
                                }
                              }
                            ]
                            name "solid(6)"
                            boundingObject USE Cloud_false_Motor
                            physics Physics {
                            }
                          }
                        }
                        DEF Cloud_Motor Shape {
                          appearance PBRAppearance {
                            baseColor 0 0 0
                          }
                          geometry Cylinder {
                            height 0.02
                            radius 0.055
                          }
                        }
                      ]
                      name "solid(5)"
                      boundingObject USE Cloud_Motor
                      physics Physics {
                      }
                    }
                  }
                ]
              }
              Group {
                children [
                  Transform {
                    translation -0.1 -0.06 -0.04
                    children [
                      Solid {
                        children [
                          DEF post Shape {
                            appearance PBRAppearance {
                              baseColor 0 0 0.498039
                            }
                            geometry Box {
                              size 0.004 0.1 0.03
                            }
                          }
                        ]
                        name "solid(15)"
                        boundingObject USE post
                        physics Physics {
                        }
                      }
                    ]
                  }
                  Transform {
                    translation 0.1 -0.06 -0.04
                    children [
                      Solid {
                        children [
                          DEF post Shape {
                            appearance PBRAppearance {
                              baseColor 0 0 0.498039
                            }
                            geometry Box {
                              size 0.004 0.1 0.03
                            }
                          }
                        ]
                        name "solid(1)"
                        boundingObject USE post
                        physics Physics {
                        }
                      }
                    ]
                  }
                  Transform {
                    translation 0.1 -0.06 0.04
                    children [
                      Solid {
                        children [
                          DEF post Shape {
                            appearance PBRAppearance {
                              baseColor 0 0 0.498039
                            }
                            geometry Box {
                              size 0.004 0.1 0.03
                            }
                          }
                        ]
                        name "solid(2)"
                        boundingObject USE post
                        physics Physics {
                        }
                      }
                    ]
                  }
                  Transform {
                    translation -0.1 -0.06 0.04
                    children [
                      Solid {
                        children [
                          DEF post Shape {
                            appearance PBRAppearance {
                              baseColor 0 0 0.498039
                            }
                            geometry Box {
                              size 0.004 0.1 0.03
                            }
                          }
                        ]
                        name "solid(3)"
                        boundingObject USE post
                        physics Physics {
                        }
                      }
                    ]
                  }
                  Transform {
                    translation -0.1 0 0
                    children [
                      Solid {
                        translation 4.04052e-07 -0.11 0
                        rotation 0 0 1 1.5708
                        children [
                          DEF disc Shape {
                            appearance PBRAppearance {
                              baseColor 0 0 0.498039
                            }
                            geometry Cylinder {
                              height 0.004
                              radius 0.055
                            }
                          }
                        ]
                        boundingObject USE disc
                        physics Physics {
                        }
                      }
                    ]
                  }
                  Transform {
                    translation 0.1 0 0
                    children [
                      Solid {
                        translation 4.04052e-07 -0.11 0
                        rotation 0 0 1 1.5708
                        children [
                          DEF disc Shape {
                            appearance PBRAppearance {
                              baseColor 0 0 0.498039
                            }
                            geometry Cylinder {
                              height 0.004
                              radius 0.055
                            }
                          }
                        ]
                        name "solid(4)"
                        boundingObject USE disc
                        physics Physics {
                        }
                      }
                    ]
                  }
                ]
              }
              DEF Cloud_disc Shape {
                appearance PBRAppearance {
                  baseColor 0 0 1
                }
                geometry Cylinder {
                  height 0.02
                  radius 0.12
                }
              }
            ]
            boundingObject USE Cloud_disc
            physics Physics {
            }
          }
        }
      ]
    }
    DEF Chaiss_Wheel Group {
      children [
        DistanceSensor {
          translation -0.055 0 5.30718e-08
          rotation 0 1 0 3.14159
          children [
            Transform {
              rotation -0.577349935856137 0.577349935856137 0.5773509358560258 2.09439
              children [
                Shape {
                  appearance PBRAppearance {
                    baseColor 1 1 0
                    metalness 0
                  }
                  geometry Cylinder {
                    height 0.01
                    radius 0.01
                  }
                }
              ]
            }
          ]
          name "laser2"
          lookupTable [
            0 0 0
            0.3 0.3 0
          ]
          aperture 0.005
        }
        DistanceSensor {
          translation 0.055 0 0
          children [
            Transform {
              rotation -0.577349935856137 0.577349935856137 0.5773509358560258 2.09439
              children [
                Shape {
                  appearance PBRAppearance {
                    baseColor 1 1 0
                    metalness 0
                  }
                  geometry Cylinder {
                    height 0.01
                    radius 0.01
                  }
                }
              ]
            }
          ]
          name "laser1"
          lookupTable [
            0 0 0
            0.3 0.3 0
          ]
          aperture 0.005
        }
        DEF Intermediate_Driven_Wheel_2 HingeJoint {
          jointParameters HingeJointParameters {
            axis 0 1 0
            anchor 0 0.08 -0.114
          }
          endPoint Solid {
            translation 0 0.08 -0.114
            rotation 1 0 0 0
            children [
              DEF Intermediate_Driven_Wheel Shape {
                appearance PBRAppearance {
                  baseColor 1 0.666667 0.498039
                }
                geometry Cylinder {
                  height 0.01
                  radius 0.015
                }
              }
            ]
            name "solid(4)"
            boundingObject USE Intermediate_Driven_Wheel
            physics Physics {
            }
          }
        }
        DEF Intermediate_Driven_Wheel_1 HingeJoint {
          jointParameters HingeJointParameters {
            axis 0 1 0
            anchor 0 0.08 0.114
          }
          endPoint Solid {
            translation 0 0.08 0.114
            rotation 1 0 0 0
            children [
              DEF Intermediate_Driven_Wheel Shape {
                appearance PBRAppearance {
                  baseColor 1 0.666667 0.498039
                }
                geometry Cylinder {
                  height 0.01
                  radius 0.015
                }
              }
            ]
            name "solid(3)"
            boundingObject USE Intermediate_Driven_Wheel
            physics Physics {
            }
          }
        }
        DEF Doen_Driven_Wheel_2 HingeJoint {
          jointParameters HingeJointParameters {
            axis 0 0 1
            anchor 0 0.035 -0.06
          }
          endPoint Solid {
            translation 0 0.035 -0.06
            rotation 1 0 0 1.5708
            children [
              DEF Doen_Driven_Wheel Shape {
                appearance PBRAppearance {
                  baseColor 1 0.666667 0.498039
                }
                geometry Cylinder {
                  height 0.015
                  radius 0.03
                }
              }
            ]
            name "solid(2)"
            boundingObject USE Doen_Driven_Wheel
            physics Physics {
            }
          }
        }
        DEF Doen_Driven_Wheel_1 HingeJoint {
          jointParameters HingeJointParameters {
            axis 0 0 1
            anchor 0 0.035 0.06
          }
          endPoint Solid {
            translation 0 0.035 0.06
            rotation 1 0 0 1.5708
            children [
              DEF Doen_Driven_Wheel Shape {
                appearance PBRAppearance {
                  baseColor 1 0.666667 0.498039
                }
                geometry Cylinder {
                  height 0.015
                  radius 0.03
                }
              }
            ]
            name "solid(1)"
            boundingObject USE Doen_Driven_Wheel
            physics Physics {
            }
          }
        }
        DEF On_Driven_Wheel_2 HingeJoint {
          jointParameters HingeJointParameters {
            axis 0 0 1
            anchor 0 0.117 0.064
          }
          device [
            RotationalMotor {
              name "motor1"
              maxVelocity 50
            }
          ]
          endPoint Solid {
            translation 0 0.117 0.064
            rotation 1 0 0 1.5708
            children [
              DEF On_Driven_Wheel Shape {
                appearance PBRAppearance {
                  baseColor 1 0.666667 0.498039
                }
                geometry Cylinder {
                  height 0.01
                  radius 0.009
                }
              }
            ]
            name "solid(5)"
            boundingObject USE On_Driven_Wheel
            physics Physics {
            }
          }
        }
        DEF On_Driven_Wheel_1 HingeJoint {
          jointParameters HingeJointParameters {
            axis 0 0 1
            anchor 0 0.117 -0.064
          }
          endPoint Solid {
            translation 0 0.117 -0.064
            rotation 1 0 0 1.5708
            children [
              DEF On_Driven_Wheel Shape {
                appearance PBRAppearance {
                  baseColor 1 0.666667 0.498039
                }
                geometry Cylinder {
                  height 0.01
                  radius 0.009
                }
              }
            ]
            name "solid(6)"
            boundingObject USE On_Driven_Wheel
            physics Physics {
            }
          }
        }
        DEF On_Driven_Wheel_3 HingeJoint {
          jointParameters HingeJointParameters {
            axis 0 0 1
            anchor -0.13 0.117 -0.064
          }
          endPoint Solid {
            translation -0.13 0.117 -0.064
            rotation 1 0 0 1.5708
            children [
              DEF On_Driven_Wheel Shape {
                appearance PBRAppearance {
                  baseColor 1 0.666667 0.498039
                }
                geometry Cylinder {
                  height 0.01
                  radius 0.009
                }
              }
            ]
            name "solid(7)"
            boundingObject USE On_Driven_Wheel
            physics Physics {
            }
          }
        }
        DEF On_Driven_Wheel_4 HingeJoint {
          jointParameters HingeJointParameters {
            axis 0 0 1
            anchor 0.13 0.117 -0.064
          }
          endPoint Solid {
            translation 0.13 0.117 -0.064
            rotation 1 0 0 1.5708
            children [
              DEF On_Driven_Wheel Shape {
                appearance PBRAppearance {
                  baseColor 1 0.666667 0.498039
                }
                geometry Cylinder {
                  height 0.01
                  radius 0.009
                }
              }
            ]
            name "solid(8)"
            boundingObject USE On_Driven_Wheel
            physics Physics {
            }
          }
        }
        DEF On_Driven_Wheel_5 HingeJoint {
          jointParameters HingeJointParameters {
            axis 0 0 1
            anchor -0.09 0.117 -0.064
          }
          endPoint Solid {
            translation -0.09 0.117 -0.064
            rotation 1 0 0 1.5708
            children [
              DEF On_Driven_Wheel Shape {
                appearance PBRAppearance {
                  baseColor 1 0.666667 0.498039
                }
                geometry Cylinder {
                  height 0.01
                  radius 0.009
                }
              }
            ]
            name "solid(9)"
            boundingObject USE On_Driven_Wheel
            physics Physics {
            }
          }
        }
        DEF On_Driven_Wheel_6 HingeJoint {
          jointParameters HingeJointParameters {
            axis 0 0 1
            anchor 0.09 0.117 -0.064
          }
          endPoint Solid {
            translation 0.09 0.117 -0.064
            rotation 1 0 0 1.5708
            children [
              DEF On_Driven_Wheel Shape {
                appearance PBRAppearance {
                  baseColor 1 0.666667 0.498039
                }
                geometry Cylinder {
                  height 0.01
                  radius 0.009
                }
              }
            ]
            name "solid(10)"
            boundingObject USE On_Driven_Wheel
            physics Physics {
            }
          }
        }
        DEF On_Driven_Wheel_3 HingeJoint {
          jointParameters HingeJointParameters {
            axis 0 0 1
            anchor -0.13 0.117 0.064
          }
          endPoint Solid {
            translation -0.13 0.117 0.064
            rotation 1 0 0 1.5708
            children [
              DEF On_Driven_Wheel Shape {
                appearance PBRAppearance {
                  baseColor 1 0.666667 0.498039
                }
                geometry Cylinder {
                  height 0.01
                  radius 0.009
                }
              }
            ]
            name "solid(11)"
            boundingObject USE On_Driven_Wheel
            physics Physics {
            }
          }
        }
        DEF On_Driven_Wheel_4 HingeJoint {
          jointParameters HingeJointParameters {
            axis 0 0 1
            anchor 0.13 0.117 0.064
          }
          endPoint Solid {
            translation 0.13 0.117 0.064
            rotation 1 0 0 1.5708
            children [
              DEF On_Driven_Wheel Shape {
                appearance PBRAppearance {
                  baseColor 1 0.666667 0.498039
                }
                geometry Cylinder {
                  height 0.01
                  radius 0.009
                }
              }
            ]
            name "solid(12)"
            boundingObject USE On_Driven_Wheel
            physics Physics {
            }
          }
        }
        DEF On_Driven_Wheel_5 HingeJoint {
          jointParameters HingeJointParameters {
            axis 0 0 1
            anchor -0.09 0.117 0.064
          }
          endPoint Solid {
            translation -0.09 0.117 0.064
            rotation 1 0 0 1.5708
            children [
              DEF On_Driven_Wheel Shape {
                appearance PBRAppearance {
                  baseColor 1 0.666667 0.498039
                }
                geometry Cylinder {
                  height 0.01
                  radius 0.009
                }
              }
            ]
            name "solid(13)"
            boundingObject USE On_Driven_Wheel
            physics Physics {
            }
          }
        }
        DEF On_Driven_Wheel_6 HingeJoint {
          jointParameters HingeJointParameters {
            axis 0 0 1
            anchor 0.09 0.117 0.064
          }
          endPoint Solid {
            translation 0.09 0.117 0.064
            rotation 1 0 0 1.5708
            children [
              DEF On_Driven_Wheel Shape {
                appearance PBRAppearance {
                  baseColor 1 0.666667 0.498039
                }
                geometry Cylinder {
                  height 0.01
                  radius 0.009
                }
              }
            ]
            name "solid(14)"
            boundingObject USE On_Driven_Wheel
            physics Physics {
            }
          }
        }
      ]
    }
    DEF Frame Transform {
      children [
        DEF Frame Group {
          children [
            Transform {
              translation -0.11 0.13 0
              children [
                Shape {
                  appearance PBRAppearance {
                    baseColor 1 0 0.498039
                  }
                  geometry Box {
                    size 0.07 0.01 0.31
                  }
                }
              ]
            }
            Transform {
              translation 0.11 0.13 0
              children [
                Shape {
                  appearance PBRAppearance {
                    baseColor 1 0 0.498039
                  }
                  geometry Box {
                    size 0.07 0.01 0.31
                  }
                }
              ]
            }
            Transform {
              translation 0 0.13 0
              children [
                Shape {
                  appearance PBRAppearance {
                    baseColor 1 0 0.498039
                  }
                  geometry Box {
                    size 0.04 0.01 0.31
                  }
                }
              ]
            }
            Transform {
              translation 0 0.08 -0.14
              children [
                Shape {
                  appearance PBRAppearance {
                    baseColor 1 0 0.498039
                  }
                  geometry Box {
                    size 0.03 0.01 0.025
                  }
                }
              ]
            }
            Transform {
              translation 0 0.08 0.14
              children [
                Shape {
                  appearance PBRAppearance {
                    baseColor 1 0 0.498039
                  }
                  geometry Box {
                    size 0.03 0.01 0.025
                  }
                }
              ]
            }
            Transform {
              translation 0 0.065 -0.16
              children [
                Shape {
                  appearance PBRAppearance {
                    baseColor 1 0 0.498039
                  }
                  geometry Box {
                    size 0.3 0.15 0.02
                  }
                }
              ]
            }
            Transform {
              translation 0 0.065 0.16
              children [
                Shape {
                  appearance PBRAppearance {
                    baseColor 1 0 0.498039
                  }
                  geometry Box {
                    size 0.3 0.15 0.02
                  }
                }
              ]
            }
            Shape {
              appearance PBRAppearance {
                baseColor 1 0 0.498039
              }
              geometry Box {
                size 0.1 0.02 0.3
              }
            }
          ]
        }
      ]
    }
  ]
  boundingObject USE Frame
  physics Physics {
    density -1
    mass 10
  }
  controller "RN_Sentry_VS"
}
Solid {
  translation 0 1.24 0
  children [
    DEF track Group {
      children [
        Transform {
          translation 0 -1.2 0
          children [
            Shape {
              appearance PBRAppearance {
                baseColor 0 0 1
              }
              geometry Box {
                size 3.4 0.05 2.9
              }
            }
          ]
        }
        Transform {
          translation 1.19 -0.57 0
          children [
            Shape {
              appearance PBRAppearance {
                baseColor 0.666667 0 0
              }
              geometry Cylinder {
                height 1.2
                radius 0.1
              }
            }
          ]
        }
        Transform {
          translation -1.19 -0.57 0
          children [
            Shape {
              appearance PBRAppearance {
                baseColor 0.666667 0 0
              }
              geometry Cylinder {
                height 1.2
                radius 0.1
              }
            }
          ]
        }
        Shape {
          appearance PBRAppearance {
            baseColor 0 0.666667 0
          }
          geometry Box {
            size 2.6 0.05 0.2
          }
        }
      ]
    }
  ]
  boundingObject USE track
  physics Physics {
    density -1
    mass 20
  }
}
