#VRML_SIM R2020b utf8
WorldInfo {
  basicTimeStep 8
  coordinateSystem "NUE"
}
Viewpoint {
  orientation 0.9591165962575143 0.2819228986598034 -0.02479584631857798 0.1828917988405901
  position 0.012111522898325573 0.4319333743930915 3.425863451110868
}
TexturedBackground {
}
TexturedBackgroundLight {
}
Floor {
}
Solid {
  translation 0 0.149117 -3.33
  rotation -0.9931847522129172 0.11585533840693421 0.012711747888494418 -1.3249550435563724e-16
  children [
    DEF BOX_1 Shape {
      appearance PBRAppearance {
        baseColor 0 1 1
        metalness 0
      }
      geometry Box {
        size 0.3 0.3 0.1
      }
    }
  ]
  name "solid(1)"
  boundingObject USE BOX_1
  physics Physics {
  }
  recognitionColors [
    0 1 1
  ]
}
DEF Sentinel Robot {
  translation -0.037916152472131634 1.1375149852920299 -0.00022416250414445532
  rotation -0.17553235098071313 0.9844480591202568 -0.007100186866759384 -0.0025759904475212373
  children [
    DEF Cloud Transform {
      translation 0 -0.02 0
      children [
        HingeJoint {
          jointParameters HingeJointParameters {
            position 109.19134421500861
            axis 0 1 0
          }
          device [
            RotationalMotor {
              name "motor2"
              maxVelocity 50
            }
          ]
          endPoint Solid {
            translation -2.0771728017411192e-10 -6.548912334869428e-06 2.0904956081454305e-10
            rotation 2.24117e-07 -1 1.42425e-07 0.240809
            children [
              DEF shoot Group {
                children [
                  HingeJoint {
                    jointParameters HingeJointParameters {
                      position -0.527929557099854
                      anchor -0.09 -0.11 0
                    }
                    device [
                      RotationalMotor {
                        name "motor3"
                        maxVelocity 80
                      }
                    ]
                    endPoint Solid {
                      translation -0.0899999 -0.11 0
                      rotation -0.252458809490963 -0.25245855208022683 -0.9340927304031227 1.6389221118620847
                      children [
                        Transform {
                          translation 0 0.09 0
                          rotation 0 0 1 -1.5707953071795862
                          children [
                            Solid {
                              rotation 1 0 0 -2.6179953071795863
                              children [
                                InertialUnit {
                                  rotation 0 1 0 -1.5708003061004252
                                  children [
                                    Transform {
                                      translation 0 0.01 0
                                      rotation 0 1 0 -1.5708003061004252
                                      children [
                                        Shape {
                                          appearance PBRAppearance {
                                            baseColor 0 1 0
                                          }
                                          geometry Cylinder {
                                            height 0.03
                                            radius 0.02
                                          }
                                        }
                                      ]
                                    }
                                  ]
                                  name "Cloud_imu"
                                }
                                DistanceSensor {
                                  translation -4.07848e-08 0.01 0.22
                                  rotation 0 1 0 -1.5707953071795862
                                  children [
                                    Transform {
                                      rotation -0.577349935856137 0.577349935856137 0.5773509358560258 2.09439
                                      children [
                                        Shape {
                                          appearance PBRAppearance {
                                            baseColor 1 1 0
                                            metalness 0
                                          }
                                          geometry Cylinder {
                                            height 0.01
                                            radius 0.01
                                          }
                                        }
                                      ]
                                    }
                                  ]
                                  name "laser0"
                                  lookupTable [
                                    0 0 0
                                    10 10 0
                                  ]
                                  type "laser"
                                  aperture 0.005
                                }
                                Camera {
                                  translation 0 0.01 0.21
                                  rotation 0 1 0 3.14159
                                  children [
                                    Transform {
                                      rotation 1 0 0 -1.5707953071795862
                                      children [
                                        Shape {
                                          appearance PBRAppearance {
                                            baseColor 1 1 0
                                            metalness 0
                                          }
                                          geometry Cylinder {
                                            height 0.04
                                            radius 0.01
                                          }
                                        }
                                      ]
                                    }
                                  ]
                                  name "camera1"
                                  width 1280
                                  height 800
                                  recognition Recognition {
                                    frameColor 0 1 0
                                    frameThickness 3
                                  }
                                }
                                Transform {
                                  translation 0 -0.01 0.07
                                  children [
                                    Solid {
                                      translation 0 0 0.06
                                      children [
                                        DEF barrel Shape {
                                          appearance PBRAppearance {
                                            baseColor 0.12549 0.12549 0.12549
                                          }
                                          geometry Box {
                                            size 0.03 0.015 0.2
                                          }
                                        }
                                      ]
                                      name "solid(8)"
                                      boundingObject USE barrel
                                      physics Physics {
                                      }
                                    }
                                  ]
                                }
                                DEF shoot_board Shape {
                                  appearance PBRAppearance {
                                    baseColor 0.12549 0.12549 0.12549
                                  }
                                  geometry Box {
                                    size 0.17 0.01 0.1
                                  }
                                }
                              ]
                              name "solid(7)"
                              boundingObject USE shoot_board
                              physics Physics {
                              }
                            }
                          ]
                        }
                        HingeJoint {
                          jointParameters HingeJointParameters {
                            position 30.129370667574623
                            axis 0 1 0
                            anchor 0 0.18 0
                          }
                          endPoint Solid {
                            translation 0 0.18 0
                            rotation 0 1 0 4.996629438856277
                            children [
                              DEF Cloud_false_Motor Shape {
                                appearance PBRAppearance {
                                  baseColor 0 0 0
                                }
                                geometry Cylinder {
                                  height 0.02
                                  radius 0.055
                                }
                              }
                            ]
                            name "solid(6)"
                            boundingObject USE Cloud_false_Motor
                            physics Physics {
                            }
                          }
                        }
                        DEF Cloud_Motor Shape {
                          appearance PBRAppearance {
                            baseColor 0 0 0
                          }
                          geometry Cylinder {
                            height 0.02
                            radius 0.055
                          }
                        }
                      ]
                      name "solid(5)"
                      boundingObject USE Cloud_Motor
                      physics Physics {
                      }
                    }
                  }
                ]
              }
              Group {
                children [
                  Transform {
                    translation -0.1 -0.06 -0.04
                    children [
                      Solid {
                        children [
                          DEF post Shape {
                            appearance PBRAppearance {
                              baseColor 0 0 0.498039
                            }
                            geometry Box {
                              size 0.004 0.1 0.03
                            }
                          }
                        ]
                        name "solid(15)"
                        boundingObject USE post
                        physics Physics {
                        }
                      }
                    ]
                  }
                  Transform {
                    translation 0.1 -0.06 -0.04
                    children [
                      Solid {
                        children [
                          DEF post Shape {
                            appearance PBRAppearance {
                              baseColor 0 0 0.498039
                            }
                            geometry Box {
                              size 0.004 0.1 0.03
                            }
                          }
                        ]
                        name "solid(1)"
                        boundingObject USE post
                        physics Physics {
                        }
                      }
                    ]
                  }
                  Transform {
                    translation 0.1 -0.06 0.04
                    children [
                      Solid {
                        children [
                          DEF post Shape {
                            appearance PBRAppearance {
                              baseColor 0 0 0.498039
                            }
                            geometry Box {
                              size 0.004 0.1 0.03
                            }
                          }
                        ]
                        name "solid(2)"
                        boundingObject USE post
                        physics Physics {
                        }
                      }
                    ]
                  }
                  Transform {
                    translation -0.1 -0.06 0.04
                    children [
                      Solid {
                        children [
                          DEF post Shape {
                            appearance PBRAppearance {
                              baseColor 0 0 0.498039
                            }
                            geometry Box {
                              size 0.004 0.1 0.03
                            }
                          }
                        ]
                        name "solid(3)"
                        boundingObject USE post
                        physics Physics {
                        }
                      }
                    ]
                  }
                  Transform {
                    translation -0.1 0 0
                    children [
                      Solid {
                        translation 4.04052e-07 -0.11 0
                        rotation 0 0 1 1.5708
                        children [
                          DEF disc Shape {
                            appearance PBRAppearance {
                              baseColor 0 0 0.498039
                            }
                            geometry Cylinder {
                              height 0.004
                              radius 0.055
                            }
                          }
                        ]
                        boundingObject USE disc
                        physics Physics {
                        }
                      }
                    ]
                  }
                  Transform {
                    translation 0.1 0 0
                    children [
                      Solid {
                        translation 4.04052e-07 -0.11 0
                        rotation 0 0 1 1.5708
                        children [
                          DEF disc Shape {
                            appearance PBRAppearance {
                              baseColor 0 0 0.498039
                            }
                            geometry Cylinder {
                              height 0.004
                              radius 0.055
                            }
                          }
                        ]
                        name "solid(4)"
                        boundingObject USE disc
                        physics Physics {
                        }
                      }
                    ]
                  }
                ]
              }
              DEF Cloud_disc Shape {
                appearance PBRAppearance {
                  baseColor 0 0 1
                }
                geometry Cylinder {
                  height 0.02
                  radius 0.12
                }
              }
            ]
            boundingObject USE Cloud_disc
            physics Physics {
            }
          }
        }
      ]
    }
    DEF Chaiss_Wheel Group {
      children [
        DistanceSensor {
          translation -0.055 0 5.30718e-08
          rotation 0 1 0 3.14159
          children [
            Transform {
              rotation -0.577349935856137 0.577349935856137 0.5773509358560258 2.09439
              children [
                Shape {
                  appearance PBRAppearance {
                    baseColor 1 1 0
                    metalness 0
                  }
                  geometry Cylinder {
                    height 0.01
                    radius 0.01
                  }
                }
              ]
            }
          ]
          name "laser2"
          lookupTable [
            0 0 0
            0.3 0.3 0
          ]
          aperture 0.005
        }
        DistanceSensor {
          translation 0.055 0 0
          children [
            Transform {
              rotation -0.577349935856137 0.577349935856137 0.5773509358560258 2.09439
              children [
                Shape {
                  appearance PBRAppearance {
                    baseColor 1 1 0
                    metalness 0
                  }
                  geometry Cylinder {
                    height 0.01
                    radius 0.01
                  }
                }
              ]
            }
          ]
          name "laser1"
          lookupTable [
            0 0 0
            0.3 0.3 0
          ]
          aperture 0.005
        }
        DEF Intermediate_Driven_Wheel_2 HingeJoint {
          jointParameters HingeJointParameters {
            position 117.49400445294232
            axis 0 1 0
            anchor 0 0.08 -0.114
          }
          endPoint Solid {
            translation 0 0.08 -0.114
            rotation 0 1 0 4.396668923709764
            children [
              DEF Intermediate_Driven_Wheel Shape {
                appearance PBRAppearance {
                  baseColor 1 0.666667 0.498039
                }
                geometry Cylinder {
                  height 0.01
                  radius 0.015
                }
              }
            ]
            name "solid(4)"
            boundingObject USE Intermediate_Driven_Wheel
            physics Physics {
            }
          }
        }
        DEF Intermediate_Driven_Wheel_1 HingeJoint {
          jointParameters HingeJointParameters {
            position 171.8727239952534
            axis 0 1 0
            anchor 0 0.08 0.114
          }
          endPoint Solid {
            translation 0 0.08 0.114
            rotation 0 -1 0 4.0564646057750124
            children [
              DEF Intermediate_Driven_Wheel Shape {
                appearance PBRAppearance {
                  baseColor 1 0.666667 0.498039
                }
                geometry Cylinder {
                  height 0.01
                  radius 0.015
                }
              }
            ]
            name "solid(3)"
            boundingObject USE Intermediate_Driven_Wheel
            physics Physics {
            }
          }
        }
        DEF Doen_Driven_Wheel_2 HingeJoint {
          jointParameters HingeJointParameters {
            position -1.2635119838330773
            axis 0 0 1
            anchor 0 0.035 -0.06
          }
          endPoint Solid {
            translation 0 0.035 -0.06
            rotation 0.6948666327786334 -0.5085087326128074 -0.5085068647593661 1.9270512231777144
            children [
              DEF Doen_Driven_Wheel Shape {
                appearance PBRAppearance {
                  baseColor 1 0.666667 0.498039
                }
                geometry Cylinder {
                  height 0.015
                  radius 0.03
                }
              }
            ]
            name "solid(2)"
            boundingObject USE Doen_Driven_Wheel
            physics Physics {
            }
          }
        }
        DEF Doen_Driven_Wheel_1 HingeJoint {
          jointParameters HingeJointParameters {
            position -1.2735817224935708
            axis 0 0 1
            anchor 0 0.035 0.06
          }
          device [
            PositionSensor {
              name "Encoder"
            }
          ]
          endPoint Solid {
            translation 0 0.035 0.06
            rotation 0.6910672787843843 -0.5110909582312402 -0.5110890808927722 1.932184775122279
            children [
              DEF Doen_Driven_Wheel Shape {
                appearance PBRAppearance {
                  baseColor 1 0.666667 0.498039
                }
                geometry Cylinder {
                  height 0.015
                  radius 0.03
                }
              }
            ]
            name "Driven_Pulley"
            boundingObject USE Doen_Driven_Wheel
            physics Physics {
            }
          }
        }
        DEF On_Driven_Wheel_2 HingeJoint {
          jointParameters HingeJointParameters {
            position 17.79999610233801
            axis 0 0 1
            anchor 0 0.117 0.064
          }
          device [
            RotationalMotor {
              name "motor1"
              maxVelocity 50
            }
          ]
          endPoint Solid {
            translation 0 0.117 0.064
            rotation -0.7737517438218436 0.4479451489971331 0.44794350360574753 4.458648580779349
            children [
              DEF On_Driven_Wheel Shape {
                appearance PBRAppearance {
                  baseColor 1 0.666667 0.498039
                }
                geometry Cylinder {
                  height 0.01
                  radius 0.009
                }
              }
            ]
            name "solid(5)"
            boundingObject USE On_Driven_Wheel
            physics Physics {
            }
          }
        }
        DEF On_Driven_Wheel_1 HingeJoint {
          jointParameters HingeJointParameters {
            position 4.210568234515483
            axis 0 0 1
            anchor 0 0.117 -0.064
          }
          endPoint Solid {
            translation 0 0.117 -0.064
            rotation -0.3861192742974638 0.6522710447313892 0.6522686488104591 3.878556710513159
            children [
              DEF On_Driven_Wheel Shape {
                appearance PBRAppearance {
                  baseColor 1 0.666667 0.498039
                }
                geometry Cylinder {
                  height 0.01
                  radius 0.009
                }
              }
            ]
            name "solid(6)"
            boundingObject USE On_Driven_Wheel
            physics Physics {
            }
          }
        }
        DEF On_Driven_Wheel_3 HingeJoint {
          jointParameters HingeJointParameters {
            position 4.210388322794334
            axis 0 0 1
            anchor -0.13 0.117 -0.064
          }
          endPoint Solid {
            translation -0.13 0.117 -0.064
            rotation -0.3860518514208612 0.6522909986270374 0.6522886026328131 3.878439357942872
            children [
              DEF On_Driven_Wheel Shape {
                appearance PBRAppearance {
                  baseColor 1 0.666667 0.498039
                }
                geometry Cylinder {
                  height 0.01
                  radius 0.009
                }
              }
            ]
            name "solid(7)"
            boundingObject USE On_Driven_Wheel
            physics Physics {
            }
          }
        }
        DEF On_Driven_Wheel_4 HingeJoint {
          jointParameters HingeJointParameters {
            position 4.210749021663764
            axis 0 0 1
            anchor 0.13 0.117 -0.064
          }
          endPoint Solid {
            translation 0.13 0.117 -0.064
            rotation -0.3861870262445378 0.6522509893216547 0.6522485934743925 3.8786746304892836
            children [
              DEF On_Driven_Wheel Shape {
                appearance PBRAppearance {
                  baseColor 1 0.666667 0.498039
                }
                geometry Cylinder {
                  height 0.01
                  radius 0.009
                }
              }
            ]
            name "solid(8)"
            boundingObject USE On_Driven_Wheel
            physics Physics {
            }
          }
        }
        DEF On_Driven_Wheel_5 HingeJoint {
          jointParameters HingeJointParameters {
            position 4.210443426070962
            axis 0 0 1
            anchor -0.09 0.117 -0.064
          }
          endPoint Solid {
            translation -0.09 0.117 -0.064
            rotation -0.38607250156211625 0.6522848876235724 0.6522824916517946 3.8784753010138173
            children [
              DEF On_Driven_Wheel Shape {
                appearance PBRAppearance {
                  baseColor 1 0.666667 0.498039
                }
                geometry Cylinder {
                  height 0.01
                  radius 0.009
                }
              }
            ]
            name "solid(9)"
            boundingObject USE On_Driven_Wheel
            physics Physics {
            }
          }
        }
        DEF On_Driven_Wheel_6 HingeJoint {
          jointParameters HingeJointParameters {
            position 4.2106930431119185
            axis 0 0 1
            anchor 0.09 0.117 -0.064
          }
          endPoint Solid {
            translation 0.09 0.117 -0.064
            rotation -0.3861660475672537 0.6522571997101896 0.6522548038401152 3.878638118383753
            children [
              DEF On_Driven_Wheel Shape {
                appearance PBRAppearance {
                  baseColor 1 0.666667 0.498039
                }
                geometry Cylinder {
                  height 0.01
                  radius 0.009
                }
              }
            ]
            name "solid(10)"
            boundingObject USE On_Driven_Wheel
            physics Physics {
            }
          }
        }
        DEF On_Driven_Wheel_3 HingeJoint {
          jointParameters HingeJointParameters {
            position 4.246219519033902
            axis 0 0 1
            anchor -0.13 0.117 0.064
          }
          endPoint Solid {
            translation -0.13 0.117 0.064
            rotation -0.39949927230442184 0.6482296731834418 0.6482272921072714 3.9017394042200024
            children [
              DEF On_Driven_Wheel Shape {
                appearance PBRAppearance {
                  baseColor 1 0.666667 0.498039
                }
                geometry Cylinder {
                  height 0.01
                  radius 0.009
                }
              }
            ]
            name "solid(11)"
            boundingObject USE On_Driven_Wheel
            physics Physics {
            }
          }
        }
        DEF On_Driven_Wheel_4 HingeJoint {
          jointParameters HingeJointParameters {
            position 4.246580076806301
            axis 0 0 1
            anchor 0.13 0.117 0.064
          }
          endPoint Solid {
            translation 0.13 0.117 0.064
            rotation -0.3996347874087205 0.6481879061112543 0.6481855251885025 3.901973120079303
            children [
              DEF On_Driven_Wheel Shape {
                appearance PBRAppearance {
                  baseColor 1 0.666667 0.498039
                }
                geometry Cylinder {
                  height 0.01
                  radius 0.009
                }
              }
            ]
            name "solid(12)"
            boundingObject USE On_Driven_Wheel
            physics Physics {
            }
          }
        }
        DEF On_Driven_Wheel_5 HingeJoint {
          jointParameters HingeJointParameters {
            position 4.246274989456103
            axis 0 0 1
            anchor -0.09 0.117 0.064
          }
          endPoint Solid {
            translation -0.09 0.117 0.064
            rotation -0.3995201205250209 0.6482232486563833 0.6482208676038111 3.9017753614833945
            children [
              DEF On_Driven_Wheel Shape {
                appearance PBRAppearance {
                  baseColor 1 0.666667 0.498039
                }
                geometry Cylinder {
                  height 0.01
                  radius 0.009
                }
              }
            ]
            name "solid(13)"
            boundingObject USE On_Driven_Wheel
            physics Physics {
            }
          }
        }
        DEF On_Driven_Wheel_6 HingeJoint {
          jointParameters HingeJointParameters {
            position 4.246524606363124
            axis 0 0 1
            anchor 0.09 0.117 0.064
          }
          endPoint Solid {
            translation 0.09 0.117 0.064
            rotation -0.3996139386695266 0.6481943329925188 0.6481919520461599 3.9019371647627077
            children [
              DEF On_Driven_Wheel Shape {
                appearance PBRAppearance {
                  baseColor 1 0.666667 0.498039
                }
                geometry Cylinder {
                  height 0.01
                  radius 0.009
                }
              }
            ]
            name "solid(14)"
            boundingObject USE On_Driven_Wheel
            physics Physics {
            }
          }
        }
      ]
    }
    DEF Frame Transform {
      children [
        DEF Frame Group {
          children [
            Transform {
              translation -0.11 0.13 0
              children [
                Shape {
                  appearance PBRAppearance {
                    baseColor 1 0 0.498039
                  }
                  geometry Box {
                    size 0.07 0.01 0.31
                  }
                }
              ]
            }
            Transform {
              translation 0.11 0.13 0
              children [
                Shape {
                  appearance PBRAppearance {
                    baseColor 1 0 0.498039
                  }
                  geometry Box {
                    size 0.07 0.01 0.31
                  }
                }
              ]
            }
            Transform {
              translation 0 0.13 0
              children [
                Shape {
                  appearance PBRAppearance {
                    baseColor 1 0 0.498039
                  }
                  geometry Box {
                    size 0.04 0.01 0.31
                  }
                }
              ]
            }
            Transform {
              translation 0 0.08 -0.14
              children [
                Shape {
                  appearance PBRAppearance {
                    baseColor 1 0 0.498039
                  }
                  geometry Box {
                    size 0.03 0.01 0.025
                  }
                }
              ]
            }
            Transform {
              translation 0 0.08 0.14
              children [
                Shape {
                  appearance PBRAppearance {
                    baseColor 1 0 0.498039
                  }
                  geometry Box {
                    size 0.03 0.01 0.025
                  }
                }
              ]
            }
            Transform {
              translation 0 0.065 -0.16
              children [
                Shape {
                  appearance PBRAppearance {
                    baseColor 1 0 0.498039
                  }
                  geometry Box {
                    size 0.3 0.15 0.02
                  }
                }
              ]
            }
            Transform {
              translation 0 0.065 0.16
              children [
                Shape {
                  appearance PBRAppearance {
                    baseColor 1 0 0.498039
                  }
                  geometry Box {
                    size 0.3 0.15 0.02
                  }
                }
              ]
            }
            Shape {
              appearance PBRAppearance {
                baseColor 1 0 0.498039
              }
              geometry Box {
                size 0.1 0.02 0.3
              }
            }
          ]
        }
      ]
    }
  ]
  boundingObject USE Frame
  physics Physics {
    density -1
    mass 10
  }
  controller "Logic_Detection"
  linearVelocity -0.22512145521089036 -1.5357384404546997e-05 -0.0005455830974194092
  angularVelocity -0.0003109029942546426 9.425126600956e-07 -3.827739630502169e-05
}
Solid {
  translation 0.0001382757483703003 1.221879875634384 1.386931143539042e-05
  rotation 0.030963571991926755 0.8827568466122481 -0.4688087104232391 -2.2996352815560714e-05
  children [
    DEF track Group {
      children [
        Transform {
          translation 0 -1.2 0
          children [
            Shape {
              appearance PBRAppearance {
                baseColor 0 0 1
              }
              geometry Box {
                size 3.4 0.05 2.9
              }
            }
          ]
        }
        Transform {
          translation 1.19 -0.57 0
          children [
            Shape {
              appearance PBRAppearance {
                baseColor 0.666667 0 0
              }
              geometry Cylinder {
                height 1.2
                radius 0.1
              }
            }
          ]
        }
        Transform {
          translation -1.19 -0.57 0
          children [
            Shape {
              appearance PBRAppearance {
                baseColor 0.666667 0 0
              }
              geometry Cylinder {
                height 1.2
                radius 0.1
              }
            }
          ]
        }
        Shape {
          appearance PBRAppearance {
            baseColor 0 0.666667 0
          }
          geometry Box {
            size 2.6 0.05 0.2
          }
        }
      ]
    }
  ]
  boundingObject USE track
  physics Physics {
    density -1
    mass 20
  }
  linearVelocity -1.5120542507845461e-05 -8.801540072329317e-06 -1.2528327117147798e-08
  angularVelocity 2.8117362430630074e-06 -6.9001560215211996e-09 9.586769366867386e-05
}
